[2023-11-24T02:31:12.446+0000] {taskinstance.py:1083} INFO - Dependencies all met for <TaskInstance: get_api_data.load_data manual__2023-11-23T22:33:54.606915+00:00 [queued]>
[2023-11-24T02:31:12.454+0000] {taskinstance.py:1083} INFO - Dependencies all met for <TaskInstance: get_api_data.load_data manual__2023-11-23T22:33:54.606915+00:00 [queued]>
[2023-11-24T02:31:12.455+0000] {taskinstance.py:1279} INFO - 
--------------------------------------------------------------------------------
[2023-11-24T02:31:12.455+0000] {taskinstance.py:1280} INFO - Starting attempt 3 of 13
[2023-11-24T02:31:12.456+0000] {taskinstance.py:1281} INFO - 
--------------------------------------------------------------------------------
[2023-11-24T02:31:12.468+0000] {taskinstance.py:1300} INFO - Executing <Task(PythonOperator): load_data> on 2023-11-23 22:33:54.606915+00:00
[2023-11-24T02:31:12.474+0000] {standard_task_runner.py:55} INFO - Started process 11936 to run task
[2023-11-24T02:31:12.476+0000] {standard_task_runner.py:82} INFO - Running: ['***', 'tasks', 'run', 'get_api_data', 'load_data', 'manual__2023-11-23T22:33:54.606915+00:00', '--job-id', '26', '--raw', '--subdir', 'DAGS_FOLDER/get_api_data.py', '--cfg-path', '/tmp/tmp1q8a52tg']
[2023-11-24T02:31:12.477+0000] {standard_task_runner.py:83} INFO - Job 26: Subtask load_data
[2023-11-24T02:31:12.530+0000] {task_command.py:388} INFO - Running <TaskInstance: get_api_data.load_data manual__2023-11-23T22:33:54.606915+00:00 [running]> on host 00af56ec80d3
[2023-11-24T02:31:12.588+0000] {taskinstance.py:1509} INFO - Exporting the following env vars:
AIRFLOW_CTX_DAG_OWNER=***
AIRFLOW_CTX_DAG_ID=get_api_data
AIRFLOW_CTX_TASK_ID=load_data
AIRFLOW_CTX_EXECUTION_DATE=2023-11-23T22:33:54.606915+00:00
AIRFLOW_CTX_TRY_NUMBER=3
AIRFLOW_CTX_DAG_RUN_ID=manual__2023-11-23T22:33:54.606915+00:00
[2023-11-24T02:31:12.590+0000] {taskinstance.py:1768} ERROR - Task failed with exception
Traceback (most recent call last):
  File "/home/airflow/.local/lib/python3.7/site-packages/airflow/operators/python.py", line 175, in execute
    return_value = self.execute_callable()
  File "/home/airflow/.local/lib/python3.7/site-packages/airflow/operators/python.py", line 192, in execute_callable
    return self.python_callable(*self.op_args, **self.op_kwargs)
  File "/opt/airflow/dags/get_api_data.py", line 140, in load
    df = extract()
  File "/opt/airflow/dags/get_api_data.py", line 18, in extract
    gu_code_dict = getcitycode()
  File "/opt/airflow/dags/get_api_data.py", line 100, in getcitycode
    code = pd.read_csv(code_file, sep='\t')
  File "/home/airflow/.local/lib/python3.7/site-packages/pandas/util/_decorators.py", line 311, in wrapper
    return func(*args, **kwargs)
  File "/home/airflow/.local/lib/python3.7/site-packages/pandas/io/parsers/readers.py", line 586, in read_csv
    return _read(filepath_or_buffer, kwds)
  File "/home/airflow/.local/lib/python3.7/site-packages/pandas/io/parsers/readers.py", line 482, in _read
    parser = TextFileReader(filepath_or_buffer, **kwds)
  File "/home/airflow/.local/lib/python3.7/site-packages/pandas/io/parsers/readers.py", line 811, in __init__
    self._engine = self._make_engine(self.engine)
  File "/home/airflow/.local/lib/python3.7/site-packages/pandas/io/parsers/readers.py", line 1040, in _make_engine
    return mapping[engine](self.f, **self.options)  # type: ignore[call-arg]
  File "/home/airflow/.local/lib/python3.7/site-packages/pandas/io/parsers/c_parser_wrapper.py", line 51, in __init__
    self._open_handles(src, kwds)
  File "/home/airflow/.local/lib/python3.7/site-packages/pandas/io/parsers/base_parser.py", line 229, in _open_handles
    errors=kwds.get("encoding_errors", "strict"),
  File "/home/airflow/.local/lib/python3.7/site-packages/pandas/io/common.py", line 707, in get_handle
    newline="",
FileNotFoundError: [Errno 2] No such file or directory: 'C:\\Users\\JONGJUN KIM\\OneDrive\\Desktop\\ETL프로젝트\\법정동코드.txt'
[2023-11-24T02:31:12.601+0000] {taskinstance.py:1323} INFO - Marking task as UP_FOR_RETRY. dag_id=get_api_data, task_id=load_data, execution_date=20231123T223354, start_date=20231124T023112, end_date=20231124T023112
[2023-11-24T02:31:12.612+0000] {standard_task_runner.py:105} ERROR - Failed to execute job 26 for task load_data ([Errno 2] No such file or directory: 'C:\\Users\\JONGJUN KIM\\OneDrive\\Desktop\\ETL프로젝트\\법정동코드.txt'; 11936)
[2023-11-24T02:31:12.648+0000] {local_task_job.py:208} INFO - Task exited with return code 1
[2023-11-24T02:31:12.663+0000] {taskinstance.py:2578} INFO - 0 downstream tasks scheduled from follow-on schedule check
